<sdf version='1.7'>
  <world name='default'>

    <include>
      <uri>model://factory_floor</uri>
    </include>

    <physics name='default_physics' default='0' type='ode'>
<!--  this factor actually is computed by multiplying the other two -->
      <real_time_factor>1</real_time_factor>
      <real_time_update_rate>1000</real_time_update_rate>
    </physics>

  <light type="directional" name="sun">
    <cast_shadows>true</cast_shadows>
    <pose>0 0 10 0 0 0</pose>
    <diffuse>0.8 0.8 0.8 1</diffuse>
    <specular>0.2 0.2 0.2 1</specular>
    <attenuation>
      <range>1000</range>
      <constant>0.9</constant>
      <linear>0.01</linear>
      <quadratic>0.001</quadratic>
    </attenuation>
    <direction>0.1 0.1 -0.9</direction>
  </light>


    <include>
      <uri>model://factory</uri>
      <pose>0 0 0</pose>
    </include>


    <include>
      <static>1</static>
      <uri>model://shelf</uri>
      <name>shelf_wall_1_2</name>
      <pose>-27 -2  0.001 0 0 0</pose>
    </include>

    <include>
      <static>1</static>
      <uri>model://shelf</uri>
      <name>shelf_wall_1_3</name>
      <pose>-24 -2  0.001 0 0 0</pose>
    </include>

    <include>
      <static>1</static>
      <uri>model://shelf</uri>
      <name>shelf_wall_1_4</name>
      <pose>-21 -2  0.001 0 0 0</pose>
    </include>

    <include>
      <static>1</static>
      <uri>model://shelf</uri>
      <name>shelf_wall_1_5</name>
      <pose>-18 -2  0.001 0 0 0</pose>
    </include>

    <include>
      <static>1</static>
      <uri>model://shelf</uri>
      <name>shelf_wall_1_6</name>
      <pose>-15 -2  0.001 0 0 0</pose>
    </include>

    <include>
      <static>1</static>
      <uri>model://shelf</uri>
      <name>shelf_wall_1_7</name>
      <pose>-12 -2  0.001 0 0 0</pose>
    </include>


    <include>
      <static>1</static>
      <uri>model://shelf</uri>
      <name>shelf_wall_1_8</name>
      <pose>-9 -2  0.001 0 0 0</pose>
    </include>

    <include>
      <static>1</static>
      <uri>model://shelf</uri>
      <name>shelf_wall_1_9</name>
      <pose>-6 -2  0.001 0 0 0</pose>
    </include>

    <include>
      <static>1</static>
      <uri>model://shelf</uri>
      <name>shelf_wall_1_10</name>
      <pose>-3 -2  0.001 0 0 0</pose>
    </include>

    <include>
      <static>1</static>
      <uri>model://shelf</uri>
      <name>shelf_wall_1_11</name>
      <pose>0 -2  0.001 0 0 0</pose>
    </include>

    <include>
      <static>1</static>
      <uri>model://shelf</uri>
      <name>shelf_wall_1_12</name>
      <pose>3 -2  0.001 0 0 0</pose>
    </include>

    <include>
      <static>1</static>
      <uri>model://shelf</uri>
      <name>shelf_wall_1_13</name>
      <pose>6 -2  0.001 0 0 0</pose>
    </include>

    <include>
      <static>1</static>
      <uri>model://shelf</uri>
      <name>shelf_wall_1_14</name>
      <pose>9 -2  0.001 0 0 0</pose>
    </include>

    <include>
      <static>1</static>
      <uri>model://shelf</uri>
      <name>shelf_wall_1_15</name>
      <pose>12 -2  0.001 0 0 0</pose>
    </include>

    <include>
      <static>1</static>
      <uri>model://shelf</uri>
      <name>shelf_wall_1_16</name>
      <pose>15 -2  0.001 0 0 0</pose>
    </include>

    <include>
      <static>1</static>
      <uri>model://shelf</uri>
      <name>shelf_wall_1_17</name>
      <pose>18 -2  0.001 0 0 0</pose>
    </include>
<!-- FORKLIFT ALLEY
    <include>
      <static>1</static>
      <uri>model://shelf</uri>
      <name>shelf_wall_1_18</name>
      <pose>21 -2  0.001 0 0 0</pose>
    </include>

    <include>
      <static>1</static>
      <uri>model://shelf</uri>
      <name>shelf_wall_1_19</name>
      <pose>24 -2  0.001 0 0 0</pose>
    </include>
-->
    <include>
      <static>1</static>
      <uri>model://shelf</uri>
      <name>shelf_wall_1_20</name>
      <pose>27 -2  0.001 0 0 0</pose>
    </include>

    <include>
      <static>1</static>
      <uri>model://shelf</uri>
      <name>shelf_wall_1_21</name>
      <pose>30 -2  0.001 0 0 0</pose>
    </include>

    <include>
      <static>1</static>
      <uri>model://shelf</uri>
      <name>shelf_wall_1_22</name>
      <pose>33 -2  0.001 0 0 0</pose>
    </include>

    <include>
      <static>1</static>
      <uri>model://shelf</uri>
      <name>shelf_wall_1_23</name>
      <pose>36 -2  0.001 0 0 0</pose>
    </include>

    <include>
      <static>1</static>
      <uri>model://shelf</uri>
      <name>shelf_wall_1_24</name>
      <pose>39 -2  0.001 0 0 0</pose>
    </include>
















    <include>
      <static>1</static>
      <uri>model://shelf</uri>
      <name>shelf_wall_2_2</name>
      <pose>-27 4  0.001 0 0 0</pose>
    </include>

    <include>
      <static>1</static>
      <uri>model://shelf</uri>
      <name>shelf_wall_2_3</name>
      <pose>-24 4  0.001 0 0 0</pose>
    </include>

    <include>
      <static>1</static>
      <uri>model://shelf</uri>
      <name>shelf_wall_2_4</name>
      <pose>-21 4  0.001 0 0 0</pose>
    </include>

    <include>
      <static>1</static>
      <uri>model://shelf</uri>
      <name>shelf_wall_2_5</name>
      <pose>-18 4  0.001 0 0 0</pose>
    </include>

<!-- PICKUP POINT
    <include>
      <static>1</static>
      <uri>model://shelf</uri>
      <name>shelf_wall_2_6</name>
      <pose>-15 4  0.001 0 0 0</pose>
    </include>
-->

    <include>
      <static>1</static>
      <uri>model://shelf</uri>
      <name>shelf_wall_2_7</name>
      <pose>-12 4  0.001 0 0 0</pose>
    </include>


    <include>
      <static>1</static>
      <uri>model://shelf</uri>
      <name>shelf_wall_2_8</name>
      <pose>-9 4  0.001 0 0 0</pose>
    </include>

    <include>
      <static>1</static>
      <uri>model://shelf</uri>
      <name>shelf_wall_2_9</name>
      <pose>-6 4  0.001 0 0 0</pose>
    </include>

    <include>
      <static>1</static>
      <uri>model://shelf</uri>
      <name>shelf_wall_2_10</name>
      <pose>-3 4  0.001 0 0 0</pose>
    </include>

    <include>
      <static>1</static>
      <uri>model://shelf</uri>
      <name>shelf_wall_2_11</name>
      <pose>0 4  0.001 0 0 0</pose>
    </include>

    <include>
      <static>1</static>
      <uri>model://shelf</uri>
      <name>shelf_wall_2_12</name>
      <pose>3 4  0.001 0 0 0</pose>
    </include>

    <include>
      <static>1</static>
      <uri>model://shelf</uri>
      <name>shelf_wall_2_13</name>
      <pose>6 4  0.001 0 0 0</pose>
    </include>

    <include>
      <static>1</static>
      <uri>model://shelf</uri>
      <name>shelf_wall_2_14</name>
      <pose>9 4  0.001 0 0 0</pose>
    </include>

    <include>
      <static>1</static>
      <uri>model://shelf</uri>
      <name>shelf_wall_2_15</name>
      <pose>12 4  0.001 0 0 0</pose>
    </include>

    <include>
      <static>1</static>
      <uri>model://shelf</uri>
      <name>shelf_wall_2_16</name>
      <pose>15 4  0.001 0 0 0</pose>
    </include>

    <include>
      <static>1</static>
      <uri>model://shelf</uri>
      <name>shelf_wall_2_17</name>
      <pose>18 4  0.001 0 0 0</pose>
    </include>
<!-- FORKLIFT ALLEY
    <include>
      <static>1</static>
      <uri>model://shelf</uri>
      <name>shelf_wall_2_18</name>
      <pose>21 4  0.001 0 0 0</pose>
    </include>

    <include>
      <static>1</static>
      <uri>model://shelf</uri>
      <name>shelf_wall_2_19</name>
      <pose>24 4  0.001 0 0 0</pose>
    </include>
-->
    <include>
      <static>1</static>
      <uri>model://shelf</uri>
      <name>shelf_wall_2_20</name>
      <pose>27 4  0.001 0 0 0</pose>
    </include>

    <include>
      <static>1</static>
      <uri>model://shelf</uri>
      <name>shelf_wall_2_21</name>
      <pose>30 4  0.001 0 0 0</pose>
    </include>

    <include>
      <static>1</static>
      <uri>model://shelf</uri>
      <name>shelf_wall_2_22</name>
      <pose>33 4  0.001 0 0 0</pose>
    </include>

    <include>
      <static>1</static>
      <uri>model://shelf</uri>
      <name>shelf_wall_2_23</name>
      <pose>36 4  0.001 0 0 0</pose>
    </include>

    <include>
      <static>1</static>
      <uri>model://shelf</uri>
      <name>shelf_wall_2_24</name>
      <pose>39 4  0.001 0 0 0</pose>
    </include>













    <include>
      <static>1</static>
      <uri>model://shelf</uri>
      <name>shelf_wall_3_2</name>
      <pose>-27 7.5  0.001 0 0 0</pose>
    </include>

    <include>
      <static>1</static>
      <uri>model://shelf</uri>
      <name>shelf_wall_3_3</name>
      <pose>-24 7.5  0.001 0 0 0</pose>
    </include>

    <include>
      <static>1</static>
      <uri>model://shelf</uri>
      <name>shelf_wall_3_4</name>
      <pose>-21 7.5  0.001 0 0 0</pose>
    </include>

    <include>
      <static>1</static>
      <uri>model://shelf</uri>
      <name>shelf_wall_3_5</name>
      <pose>-18 7.5  0.001 0 0 0</pose>
    </include>

    <include>
      <static>1</static>
      <uri>model://shelf</uri>
      <name>shelf_wall_3_6</name>
      <pose>-15 7.5  0.001 0 0 0</pose>
    </include>

    <include>
      <static>1</static>
      <uri>model://shelf</uri>
      <name>shelf_wall_3_7</name>
      <pose>-12 7.5  0.001 0 0 0</pose>
    </include>


    <include>
      <static>1</static>
      <uri>model://shelf</uri>
      <name>shelf_wall_3_8</name>
      <pose>-9 7.5  0.001 0 0 0</pose>
    </include>

    <include>
      <static>1</static>
      <uri>model://shelf</uri>
      <name>shelf_wall_3_9</name>
      <pose>-6 7.5  0.001 0 0 0</pose>
    </include>

    <include>
      <static>1</static>
      <uri>model://shelf</uri>
      <name>shelf_wall_3_10</name>
      <pose>-3 7.5  0.001 0 0 0</pose>
    </include>

    <include>
      <static>1</static>
      <uri>model://shelf</uri>
      <name>shelf_wall_3_11</name>
      <pose>0 7.5  0.001 0 0 0</pose>
    </include>

    <include>
      <static>1</static>
      <uri>model://shelf</uri>
      <name>shelf_wall_3_12</name>
      <pose>3 7.5  0.001 0 0 0</pose>
    </include>

    <include>
      <static>1</static>
      <uri>model://shelf</uri>
      <name>shelf_wall_3_13</name>
      <pose>6 7.5  0.001 0 0 0</pose>
    </include>

    <include>
      <static>1</static>
      <uri>model://shelf</uri>
      <name>shelf_wall_3_14</name>
      <pose>9 7.5  0.001 0 0 0</pose>
    </include>

    <include>
      <static>1</static>
      <uri>model://shelf</uri>
      <name>shelf_wall_3_15</name>
      <pose>12 7.5  0.001 0 0 0</pose>
    </include>

    <include>
      <static>1</static>
      <uri>model://shelf</uri>
      <name>shelf_wall_3_16</name>
      <pose>15 7.5  0.001 0 0 0</pose>
    </include>

    <include>
      <static>1</static>
      <uri>model://shelf</uri>
      <name>shelf_wall_3_17</name>
      <pose>18 7.5  0.001 0 0 0</pose>
    </include>
<!-- FORKLIFT ALLEY
    <include>
      <static>1</static>
      <uri>model://shelf</uri>
      <name>shelf_wall_3_18</name>
      <pose>21 7.5  0.001 0 0 0</pose>
    </include>


    <include>
      <static>1</static>
      <uri>model://shelf</uri>
      <name>shelf_wall_3_19</name>
      <pose>24 7.5  0.001 0 0 0</pose>
    </include>
-->

    <include>
      <static>1</static>
      <uri>model://shelf</uri>
      <name>shelf_wall_3_20</name>
      <pose>27 7.5  0.001 0 0 0</pose>
    </include>

<!-- DROP OFF POINT
    <include>
      <static>1</static>
      <uri>model://shelf</uri>
      <name>shelf_wall_3_21</name>
      <pose>30 7.5  0.001 0 0 0</pose>
    </include>
-->
    <include>
      <static>1</static>
      <uri>model://shelf</uri>
      <name>shelf_wall_3_22</name>
      <pose>33 7.5  0.001 0 0 0</pose>
    </include>

    <include>
      <static>1</static>
      <uri>model://shelf</uri>
      <name>shelf_wall_3_23</name>
      <pose>36 7.5  0.001 0 0 0</pose>
    </include>

    <include>
      <static>1</static>
      <uri>model://shelf</uri>
      <name>shelf_wall_3_24</name>
      <pose>39 7.5  0.001 0 0 0</pose>
    </include>








    <include>
      <uri>model://eur_pallet</uri>
      <name>pallet_group_pickup</name>
      <pose>26 27 0.001 0 0 0</pose>
    </include>


    <include>
      <uri>model://box_1185x785x1010</uri>
      <name>box_group_pickup</name>
      <pose>24 20 0.4 0 0 0</pose>
    </include>




    <include>
      <uri>model://eur_pallet</uri>
      <name>pallet_group_dropoff</name>
      <pose>31 8 0.001 0 -0 0</pose>
    </include>





    <actor name="test_actor">
      <link name="body">
      <!-- ATTACK ARUCO TO THE BODY
      <visual name="aruco_front_face">
        <pose>0 0.7 0 0 0 1.57 </pose>
        <geometry>
          <box>
            <size>0.0001 0.5 0.5</size>
          </box>
        </geometry>
        <material>
          <script>
            <uri>model://aruco/materials/scripts</uri>
            <uri>model://aruco/materials/textures</uri>
            <name>aruco_0</name>
          </script>
        </material>
      </visual>
      -->
      </link>
      <skin>
        <filename>walk.dae</filename>
      </skin>
      <animation name="walking">
        <filename>walk.dae</filename>
        <interpolate_x>true</interpolate_x>
      </animation>
      <script>
        <loop>1</loop>
        <auto_start>1</auto_start>
        <trajectory id="0" type="walking" tension="1">
          <waypoint>
            <time>0</time>
            <pose>25 0 0 0 0 1.57</pose>
          </waypoint>

          <waypoint>
            <time>5</time>
            <pose>25 10 0 0 0 1.57</pose>
          </waypoint>

          <waypoint>
            <time>5.5</time>
            <pose>25 10 0 0 0 4.71</pose>
          </waypoint>

          <waypoint>
            <time>10</time>
            <pose>25 0 0 0 0 4.71</pose>
          </waypoint>

          <waypoint>
            <time>10.5</time>
            <pose>25 0 0 0 0 1.57</pose>
          </waypoint>



        </trajectory>
      </script>
    </actor>

  <!-- Objects for data collection-->

    <include>
      <uri>model://eur_pallet</uri>
      <name>eur_pallet</name>
      <pose>25 25 0.1 0 0 0</pose>
    </include>

    <include>
      <uri>model://eur_pallet</uri>
      <name>smaller_pallet</name>
      <!-- Rescale the model-->
      <mesh scale="0.5 0.5 0.5">model://eur_pallet</mesh>
      <pose>25  26 0.4 0 0 0</pose>
    </include>

    <include>
      <uri>model://traffic_cone</uri>
      <name>traffic_cone</name>
      <pose>25 28 0.4 0 0 0</pose>
    </include>

    <light name='user_spot_light_0' type='spot'>
      <pose>20.0 20.0 1 0 0 0</pose>
      <diffuse>0.5 0.5 0.5 1</diffuse>
      <specular>0.1 0.1 0.1 1</specular>
      <direction>0 0 -1</direction>
      <attenuation>
        <range>20</range>
        <constant>0.5</constant>
        <linear>0.01</linear>
        <quadratic>0.001</quadratic>
      </attenuation>
      <cast_shadows>0</cast_shadows>
      <spot>
        <inner_angle>0.6</inner_angle>
        <outer_angle>1</outer_angle>
        <falloff>1</falloff>
      </spot>
    </light>

    <!-- Jackal -->
    <model name='jackal'>
      <link name='jackal_base_link'>
        <inertial>
          <pose>0.011999 0.002 0.066996 0 -0 0</pose>
          <mass>16.524</mass>
          <inertia>
            <ixx>0.313604</ixx>
            <ixy>-0.000800024</ixy>
            <ixz>0.0163992</ixz>
            <iyy>0.392205</iyy>
            <iyz>-0.000900134</iyz>
            <izz>0.4485</izz>
          </inertia>
        </inertial>
        <collision name='jackal_base_link_fixed_joint_lump__jackal_chassis_link_collision'>
          <pose>0 0 0.092 0 -0 0</pose>
          <geometry>
            <box>
              <size>0.42 0.31 0.184</size>
            </box>
          </geometry>
          <surface>
            <contact>
              <ode/>
            </contact>
            <friction>
              <ode/>
              <torsional>
                <ode/>
              </torsional>
            </friction>
            <bounce/>
          </surface>
          <max_contacts>10</max_contacts>
        </collision>
        <visual name='jackal_base_link_fixed_joint_lump__jackal_chassis_link_visual'>
          <pose>0 0 -0.0655 1.5708 -0 1.5708</pose>
          <geometry>
            <mesh>
              <scale>1 1 1</scale>
              <uri>file:///home/ros/install/share/jackal_description/meshes/jackal-base.stl</uri>
            </mesh>
          </geometry>
          <material>
            <script>
              <name>Gazebo/DarkGrey</name>
              <uri>file://media/materials/scripts/gazebo.material</uri>
            </script>
          </material>
        </visual>
        <visual name='jackal_base_link_fixed_joint_lump__jackal_front_fender_link_visual_1'>
          <pose>0 0 0 0 -0 0</pose>
          <geometry>
            <mesh>
              <scale>1 1 1</scale>
              <uri>file:///home/ros/install/share/jackal_description/meshes/jackal-fender.stl</uri>
            </mesh>
          </geometry>
          <material>
            <script>
              <name>Gazebo/Yellow</name>
              <uri>file://media/materials/scripts/gazebo.material</uri>
            </script>
          </material>
        </visual>
        <visual name='jackal_base_link_fixed_joint_lump__jackal_navsat_link_visual_2'>
          <pose>-0.18 0.126 0.1895 0 -0 0</pose>
          <geometry>
            <cylinder>
              <length>0.016</length>
              <radius>0.026</radius>
            </cylinder>
          </geometry>
          <material>
            <script>
              <name>Gazebo/DarkGrey</name>
              <uri>file://media/materials/scripts/gazebo.material</uri>
            </script>
          </material>
        </visual>
        <visual name='jackal_base_link_fixed_joint_lump__jackal_rear_fender_link_visual_3'>
          <pose>0 0 0 0 -0 3.14159</pose>
          <geometry>
            <mesh>
              <scale>1 1 1</scale>
              <uri>file:///home/ros/install/share/jackal_description/meshes/jackal-fender.stl</uri>
            </mesh>
          </geometry>
          <material>
            <script>
              <name>Gazebo/Yellow</name>
              <uri>file://media/materials/scripts/gazebo.material</uri>
            </script>
          </material>
        </visual>
        <sensor name='jackal_imu_sensor' type='imu'>
          <always_on>1</always_on>
          <update_rate>50</update_rate>
          <imu>
            <angular_velocity>
              <x>
                <noise type='gaussian'>
                  <mean>0</mean>
                  <stddev>0.0002</stddev>
                </noise>
              </x>
              <y>
                <noise type='gaussian'>
                  <mean>0</mean>
                  <stddev>0.0002</stddev>
                </noise>
              </y>
              <z>
                <noise type='gaussian'>
                  <mean>0</mean>
                  <stddev>0.0002</stddev>
                </noise>
              </z>
            </angular_velocity>
            <linear_acceleration>
              <x>
                <noise type='gaussian'>
                  <mean>0</mean>
                  <stddev>0.017</stddev>
                </noise>
              </x>
              <y>
                <noise type='gaussian'>
                  <mean>0</mean>
                  <stddev>0.017</stddev>
                </noise>
              </y>
              <z>
                <noise type='gaussian'>
                  <mean>0</mean>
                  <stddev>0.017</stddev>
                </noise>
              </z>
            </linear_acceleration>
          </imu>
          <plugin name='imu_plugin' filename='libgazebo_ros_imu_sensor.so'>
            <ros>
              <namespace>jackal</namespace>
              <remapping>~/out:=/jackal/imu/data</remapping>
            </ros>
            <body_name>jackal_imu_link</body_name>
            <frame_name>jackal_imu_link</frame_name>
            <initial_orientation_as_reference>0</initial_orientation_as_reference>
          </plugin>
          <always_on>1</always_on>
          <update_rate>100</update_rate>
          <visualize>1</visualize>
          <pose>0 0 0 0 -0 0</pose>
        </sensor>
        <gravity>1</gravity>
        <self_collide>0</self_collide>
        <enable_wind>0</enable_wind>
        <kinematic>0</kinematic>
      </link>
      <joint name='jackal_front_left_wheel_joint' type='revolute'>
        <pose relative_to='jackal_base_link'>0.131 0.187795 0.0345 0 -0 0</pose>
        <parent>jackal_base_link</parent>
        <child>jackal_front_left_wheel_link</child>
        <axis>
          <xyz>0 1 0</xyz>
          <limit>
            <lower>-1e+16</lower>
            <upper>1e+16</upper>
          </limit>
          <dynamics>
            <spring_reference>0</spring_reference>
            <spring_stiffness>0</spring_stiffness>
          </dynamics>
        </axis>
      </joint>
      <link name='jackal_front_left_wheel_link'>
        <pose relative_to='jackal_front_left_wheel_joint'>0 0 0 0 -0 0</pose>
        <inertial>
          <pose>0 0 0 0 -0 0</pose>
          <mass>0.477</mass>
          <inertia>
            <ixx>0.0013</ixx>
            <ixy>0</ixy>
            <ixz>0</ixz>
            <iyy>0.0024</iyy>
            <iyz>0</iyz>
            <izz>0.0013</izz>
          </inertia>
        </inertial>
        <collision name='jackal_front_left_wheel_link_collision'>
          <pose>0 0 0 1.5708 -0 0</pose>
          <geometry>
            <cylinder>
              <length>0.04</length>
              <radius>0.098</radius>
            </cylinder>
          </geometry>
          <surface>
            <contact>
              <ode>
                <kp>1e+07</kp>
                <kd>1</kd>
              </ode>
            </contact>
            <friction>
              <ode>
                <mu>0.5</mu>
                <mu2>0.5</mu2>
                <fdir1>1 0 0</fdir1>
              </ode>
              <torsional>
                <ode/>
              </torsional>
            </friction>
            <bounce/>
          </surface>
          <max_contacts>10</max_contacts>
        </collision>
        <visual name='jackal_front_left_wheel_link_visual'>
          <pose>0 0 0 1.5708 -0 0</pose>
          <geometry>
            <mesh>
              <scale>1 1 1</scale>
              <uri>file:///home/ros/install/share/jackal_description/meshes/jackal-wheel.stl</uri>
            </mesh>
          </geometry>
          <material>
            <script>
              <name>Gazebo/DarkGrey</name>
              <uri>file://media/materials/scripts/gazebo.material</uri>
            </script>
          </material>
        </visual>
        <self_collide>0</self_collide>
        <enable_wind>0</enable_wind>
        <kinematic>0</kinematic>
      </link>
      <joint name='jackal_front_right_wheel_joint' type='revolute'>
        <pose relative_to='jackal_base_link'>0.131 -0.187795 0.0345 0 -0 0</pose>
        <parent>jackal_base_link</parent>
        <child>jackal_front_right_wheel_link</child>
        <axis>
          <xyz>0 1 0</xyz>
          <limit>
            <lower>-1e+16</lower>
            <upper>1e+16</upper>
          </limit>
          <dynamics>
            <spring_reference>0</spring_reference>
            <spring_stiffness>0</spring_stiffness>
          </dynamics>
        </axis>
      </joint>
      <link name='jackal_front_right_wheel_link'>
        <pose relative_to='jackal_front_right_wheel_joint'>0 0 0 0 -0 0</pose>
        <inertial>
          <pose>0 0 0 0 -0 0</pose>
          <mass>0.477</mass>
          <inertia>
            <ixx>0.0013</ixx>
            <ixy>0</ixy>
            <ixz>0</ixz>
            <iyy>0.0024</iyy>
            <iyz>0</iyz>
            <izz>0.0013</izz>
          </inertia>
        </inertial>
        <collision name='jackal_front_right_wheel_link_collision'>
          <pose>0 0 0 1.5708 -0 0</pose>
          <geometry>
            <cylinder>
              <length>0.04</length>
              <radius>0.098</radius>
            </cylinder>
          </geometry>
          <surface>
            <contact>
              <ode>
                <kp>1e+07</kp>
                <kd>1</kd>
              </ode>
            </contact>
            <friction>
              <ode>
                <mu>0.5</mu>
                <mu2>0.5</mu2>
                <fdir1>1 0 0</fdir1>
              </ode>
              <torsional>
                <ode/>
              </torsional>
            </friction>
            <bounce/>
          </surface>
          <max_contacts>10</max_contacts>
        </collision>
        <visual name='jackal_front_right_wheel_link_visual'>
          <pose>0 0 0 1.5708 -0 0</pose>
          <geometry>
            <mesh>
              <scale>1 1 1</scale>
              <uri>file:///home/ros/install/share/jackal_description/meshes/jackal-wheel.stl</uri>
            </mesh>
          </geometry>
          <material>
            <script>
              <name>Gazebo/DarkGrey</name>
              <uri>file://media/materials/scripts/gazebo.material</uri>
            </script>
          </material>
        </visual>
        <self_collide>0</self_collide>
        <enable_wind>0</enable_wind>
        <kinematic>0</kinematic>
      </link>
      <joint name='jackal_rear_left_wheel_joint' type='revolute'>
        <pose relative_to='jackal_base_link'>-0.131 0.187795 0.0345 0 -0 0</pose>
        <parent>jackal_base_link</parent>
        <child>jackal_rear_left_wheel_link</child>
        <axis>
          <xyz>0 1 0</xyz>
          <limit>
            <lower>-1e+16</lower>
            <upper>1e+16</upper>
          </limit>
          <dynamics>
            <spring_reference>0</spring_reference>
            <spring_stiffness>0</spring_stiffness>
          </dynamics>
        </axis>
      </joint>
      <link name='jackal_rear_left_wheel_link'>
        <pose relative_to='jackal_rear_left_wheel_joint'>0 0 0 0 -0 0</pose>
        <inertial>
          <pose>0 0 0 0 -0 0</pose>
          <mass>0.477</mass>
          <inertia>
            <ixx>0.0013</ixx>
            <ixy>0</ixy>
            <ixz>0</ixz>
            <iyy>0.0024</iyy>
            <iyz>0</iyz>
            <izz>0.0013</izz>
          </inertia>
        </inertial>
        <collision name='jackal_rear_left_wheel_link_collision'>
          <pose>0 0 0 1.5708 -0 0</pose>
          <geometry>
            <cylinder>
              <length>0.04</length>
              <radius>0.098</radius>
            </cylinder>
          </geometry>
          <surface>
            <contact>
              <ode>
                <kp>1e+07</kp>
                <kd>1</kd>
              </ode>
            </contact>
            <friction>
              <ode>
                <mu>0.5</mu>
                <mu2>0.5</mu2>
                <fdir1>1 0 0</fdir1>
              </ode>
              <torsional>
                <ode/>
              </torsional>
            </friction>
            <bounce/>
          </surface>
          <max_contacts>10</max_contacts>
        </collision>
        <visual name='jackal_rear_left_wheel_link_visual'>
          <pose>0 0 0 1.5708 -0 0</pose>
          <geometry>
            <mesh>
              <scale>1 1 1</scale>
              <uri>file:///home/ros/install/share/jackal_description/meshes/jackal-wheel.stl</uri>
            </mesh>
          </geometry>
          <material>
            <script>
              <name>Gazebo/DarkGrey</name>
              <uri>file://media/materials/scripts/gazebo.material</uri>
            </script>
          </material>
        </visual>
        <self_collide>0</self_collide>
        <enable_wind>0</enable_wind>
        <kinematic>0</kinematic>
      </link>
      <joint name='jackal_rear_right_wheel_joint' type='revolute'>
        <pose relative_to='jackal_base_link'>-0.131 -0.187795 0.0345 0 -0 0</pose>
        <parent>jackal_base_link</parent>
        <child>jackal_rear_right_wheel_link</child>
        <axis>
          <xyz>0 1 0</xyz>
          <limit>
            <lower>-1e+16</lower>
            <upper>1e+16</upper>
          </limit>
          <dynamics>
            <spring_reference>0</spring_reference>
            <spring_stiffness>0</spring_stiffness>
          </dynamics>
        </axis>
      </joint>
      <link name='jackal_rear_right_wheel_link'>
        <pose relative_to='jackal_rear_right_wheel_joint'>0 0 0 0 -0 0</pose>
        <inertial>
          <pose>0 0 0 0 -0 0</pose>
          <mass>0.477</mass>
          <inertia>
            <ixx>0.0013</ixx>
            <ixy>0</ixy>
            <ixz>0</ixz>
            <iyy>0.0024</iyy>
            <iyz>0</iyz>
            <izz>0.0013</izz>
          </inertia>
        </inertial>
        <collision name='jackal_rear_right_wheel_link_collision'>
          <pose>0 0 0 1.5708 -0 0</pose>
          <geometry>
            <cylinder>
              <length>0.04</length>
              <radius>0.098</radius>
            </cylinder>
          </geometry>
          <surface>
            <contact>
              <ode>
                <kp>1e+07</kp>
                <kd>1</kd>
              </ode>
            </contact>
            <friction>
              <ode>
                <mu>0.5</mu>
                <mu2>0.5</mu2>
                <fdir1>1 0 0</fdir1>
              </ode>
              <torsional>
                <ode/>
              </torsional>
            </friction>
            <bounce/>
          </surface>
          <max_contacts>10</max_contacts>
        </collision>
        <visual name='jackal_rear_right_wheel_link_visual'>
          <pose>0 0 0 1.5708 -0 0</pose>
          <geometry>
            <mesh>
              <scale>1 1 1</scale>
              <uri>file:///home/ros/install/share/jackal_description/meshes/jackal-wheel.stl</uri>
            </mesh>
          </geometry>
          <material>
            <script>
              <name>Gazebo/DarkGrey</name>
              <uri>file://media/materials/scripts/gazebo.material</uri>
            </script>
          </material>
        </visual>
        <self_collide>0</self_collide>
        <enable_wind>0</enable_wind>
        <kinematic>0</kinematic>
      </link>
      <static>0</static>
      <pose>0 2 0.2 0 -0 0</pose>
    </model>

    <plugin name="gazebo_ros_state" filename="libgazebo_ros_state.so">
      <ros>
        <namespace>/gazebo</namespace>
      </ros>
      <update_rate>1.0</update_rate>
    </plugin>

    <gui fullscreen='0'>
      <camera name='user_camera'>
        <pose>26.8898 11.6672 18.7547 -0 0.649796 -3.003</pose>
        <view_controller>orbit</view_controller>
        <projection_type>perspective</projection_type>
      </camera>
    </gui>
  </world>
</sdf>
